[2023-08-09T03:59:59.691+0000] {taskinstance.py:1103} INFO - Dependencies all met for dep_context=non-requeueable deps ti=<TaskInstance: local_gcd_etl_basic.upload_file manual__2023-08-09T03:59:54.664355+00:00 [queued]>
[2023-08-09T03:59:59.701+0000] {taskinstance.py:1103} INFO - Dependencies all met for dep_context=requeueable deps ti=<TaskInstance: local_gcd_etl_basic.upload_file manual__2023-08-09T03:59:54.664355+00:00 [queued]>
[2023-08-09T03:59:59.702+0000] {taskinstance.py:1308} INFO - Starting attempt 1 of 1
[2023-08-09T03:59:59.715+0000] {taskinstance.py:1327} INFO - Executing <Task(LocalFilesystemToGCSOperator): upload_file> on 2023-08-09 03:59:54.664355+00:00
[2023-08-09T03:59:59.721+0000] {standard_task_runner.py:57} INFO - Started process 510 to run task
[2023-08-09T03:59:59.725+0000] {standard_task_runner.py:84} INFO - Running: ['***', 'tasks', 'run', 'local_gcd_etl_basic', 'upload_file', 'manual__2023-08-09T03:59:54.664355+00:00', '--job-id', '51', '--raw', '--subdir', 'DAGS_FOLDER/example_gcs_upload_download.py', '--cfg-path', '/tmp/tmp1ehz5g91']
[2023-08-09T03:59:59.727+0000] {standard_task_runner.py:85} INFO - Job 51: Subtask upload_file
[2023-08-09T03:59:59.768+0000] {task_command.py:410} INFO - Running <TaskInstance: local_gcd_etl_basic.upload_file manual__2023-08-09T03:59:54.664355+00:00 [running]> on host 738c524d2ce7
[2023-08-09T03:59:59.845+0000] {taskinstance.py:1547} INFO - Exporting env vars: AIRFLOW_CTX_DAG_OWNER='***' AIRFLOW_CTX_DAG_ID='local_gcd_etl_basic' AIRFLOW_CTX_TASK_ID='upload_file' AIRFLOW_CTX_EXECUTION_DATE='2023-08-09T03:59:54.664355+00:00' AIRFLOW_CTX_TRY_NUMBER='1' AIRFLOW_CTX_DAG_RUN_ID='manual__2023-08-09T03:59:54.664355+00:00'
[2023-08-09T03:59:59.854+0000] {base.py:73} INFO - Using connection ID 'admin' for task execution.
[2023-08-09T03:59:59.856+0000] {taskinstance.py:1824} ERROR - Task failed with exception
Traceback (most recent call last):
  File "/home/airflow/.local/lib/python3.7/site-packages/airflow/providers/google/cloud/transfers/local_to_gcs.py", line 98, in execute
    raise FileNotFoundError(self.src)
FileNotFoundError: /opt/***/dags/resources/mock_users.csv
[2023-08-09T03:59:59.864+0000] {taskinstance.py:1350} INFO - Marking task as FAILED. dag_id=local_gcd_etl_basic, task_id=upload_file, execution_date=20230809T035954, start_date=20230809T035959, end_date=20230809T035959
[2023-08-09T03:59:59.874+0000] {standard_task_runner.py:109} ERROR - Failed to execute job 51 for task upload_file (/opt/***/dags/resources/mock_users.csv; 510)
[2023-08-09T03:59:59.896+0000] {local_task_job_runner.py:225} INFO - Task exited with return code 1
[2023-08-09T03:59:59.933+0000] {taskinstance.py:2653} INFO - 0 downstream tasks scheduled from follow-on schedule check
