[2023-08-09T03:53:03.693+0000] {taskinstance.py:1103} INFO - Dependencies all met for dep_context=non-requeueable deps ti=<TaskInstance: local_gcd_etl_basic.upload_file manual__2023-08-09T03:52:58.790263+00:00 [queued]>
[2023-08-09T03:53:03.702+0000] {taskinstance.py:1103} INFO - Dependencies all met for dep_context=requeueable deps ti=<TaskInstance: local_gcd_etl_basic.upload_file manual__2023-08-09T03:52:58.790263+00:00 [queued]>
[2023-08-09T03:53:03.702+0000] {taskinstance.py:1308} INFO - Starting attempt 1 of 1
[2023-08-09T03:53:03.715+0000] {taskinstance.py:1327} INFO - Executing <Task(LocalFilesystemToGCSOperator): upload_file> on 2023-08-09 03:52:58.790263+00:00
[2023-08-09T03:53:03.721+0000] {standard_task_runner.py:57} INFO - Started process 375 to run task
[2023-08-09T03:53:03.724+0000] {standard_task_runner.py:84} INFO - Running: ['***', 'tasks', 'run', 'local_gcd_etl_basic', 'upload_file', 'manual__2023-08-09T03:52:58.790263+00:00', '--job-id', '47', '--raw', '--subdir', 'DAGS_FOLDER/example_gcs_upload_download.py', '--cfg-path', '/tmp/tmpi3z1zapc']
[2023-08-09T03:53:03.727+0000] {standard_task_runner.py:85} INFO - Job 47: Subtask upload_file
[2023-08-09T03:53:03.776+0000] {task_command.py:410} INFO - Running <TaskInstance: local_gcd_etl_basic.upload_file manual__2023-08-09T03:52:58.790263+00:00 [running]> on host 738c524d2ce7
[2023-08-09T03:53:03.902+0000] {taskinstance.py:1547} INFO - Exporting env vars: AIRFLOW_CTX_DAG_OWNER='***' AIRFLOW_CTX_DAG_ID='local_gcd_etl_basic' AIRFLOW_CTX_TASK_ID='upload_file' AIRFLOW_CTX_EXECUTION_DATE='2023-08-09T03:52:58.790263+00:00' AIRFLOW_CTX_TRY_NUMBER='1' AIRFLOW_CTX_DAG_RUN_ID='manual__2023-08-09T03:52:58.790263+00:00'
[2023-08-09T03:53:03.916+0000] {base.py:73} INFO - Using connection ID 'admin' for task execution.
[2023-08-09T03:53:03.920+0000] {taskinstance.py:1824} ERROR - Task failed with exception
Traceback (most recent call last):
  File "/home/airflow/.local/lib/python3.7/site-packages/airflow/providers/google/cloud/transfers/local_to_gcs.py", line 98, in execute
    raise FileNotFoundError(self.src)
FileNotFoundError: /opt/***/dags/mock_users.csv
[2023-08-09T03:53:03.934+0000] {taskinstance.py:1350} INFO - Marking task as FAILED. dag_id=local_gcd_etl_basic, task_id=upload_file, execution_date=20230809T035258, start_date=20230809T035303, end_date=20230809T035303
[2023-08-09T03:53:03.952+0000] {standard_task_runner.py:109} ERROR - Failed to execute job 47 for task upload_file (/opt/***/dags/mock_users.csv; 375)
[2023-08-09T03:53:03.975+0000] {local_task_job_runner.py:225} INFO - Task exited with return code 1
[2023-08-09T03:53:04.002+0000] {taskinstance.py:2653} INFO - 0 downstream tasks scheduled from follow-on schedule check
