[2023-08-08T10:35:53.549+0000] {taskinstance.py:1103} INFO - Dependencies all met for dep_context=non-requeueable deps ti=<TaskInstance: local_gcd_gbq.upload_file manual__2023-08-08T10:35:52.411032+00:00 [queued]>
[2023-08-08T10:35:53.556+0000] {taskinstance.py:1103} INFO - Dependencies all met for dep_context=requeueable deps ti=<TaskInstance: local_gcd_gbq.upload_file manual__2023-08-08T10:35:52.411032+00:00 [queued]>
[2023-08-08T10:35:53.556+0000] {taskinstance.py:1308} INFO - Starting attempt 1 of 1
[2023-08-08T10:35:53.567+0000] {taskinstance.py:1327} INFO - Executing <Task(LocalFilesystemToGCSOperator): upload_file> on 2023-08-08 10:35:52.411032+00:00
[2023-08-08T10:35:53.574+0000] {standard_task_runner.py:57} INFO - Started process 450 to run task
[2023-08-08T10:35:53.577+0000] {standard_task_runner.py:84} INFO - Running: ['***', 'tasks', 'run', 'local_gcd_gbq', 'upload_file', 'manual__2023-08-08T10:35:52.411032+00:00', '--job-id', '26', '--raw', '--subdir', 'DAGS_FOLDER/gcs/example_gcs_upload_download.py', '--cfg-path', '/tmp/tmpx6eyxetx']
[2023-08-08T10:35:53.578+0000] {standard_task_runner.py:85} INFO - Job 26: Subtask upload_file
[2023-08-08T10:35:53.637+0000] {task_command.py:410} INFO - Running <TaskInstance: local_gcd_gbq.upload_file manual__2023-08-08T10:35:52.411032+00:00 [running]> on host eb6c146e2e2c
[2023-08-08T10:35:53.698+0000] {taskinstance.py:1547} INFO - Exporting env vars: AIRFLOW_CTX_DAG_OWNER='***' AIRFLOW_CTX_DAG_ID='local_gcd_gbq' AIRFLOW_CTX_TASK_ID='upload_file' AIRFLOW_CTX_EXECUTION_DATE='2023-08-08T10:35:52.411032+00:00' AIRFLOW_CTX_TRY_NUMBER='1' AIRFLOW_CTX_DAG_RUN_ID='manual__2023-08-08T10:35:52.411032+00:00'
[2023-08-08T10:35:53.705+0000] {base.py:73} INFO - Using connection ID 'admin' for task execution.
[2023-08-08T10:35:53.707+0000] {taskinstance.py:1824} ERROR - Task failed with exception
Traceback (most recent call last):
  File "/home/airflow/.local/lib/python3.7/site-packages/airflow/providers/google/cloud/transfers/local_to_gcs.py", line 98, in execute
    raise FileNotFoundError(self.src)
FileNotFoundError: /opt/***/dags/gcs/resources/mock_users.csv
[2023-08-08T10:35:53.713+0000] {taskinstance.py:1350} INFO - Marking task as FAILED. dag_id=local_gcd_gbq, task_id=upload_file, execution_date=20230808T103552, start_date=20230808T103553, end_date=20230808T103553
[2023-08-08T10:35:53.720+0000] {standard_task_runner.py:109} ERROR - Failed to execute job 26 for task upload_file (/opt/***/dags/gcs/resources/mock_users.csv; 450)
[2023-08-08T10:35:53.748+0000] {local_task_job_runner.py:225} INFO - Task exited with return code 1
[2023-08-08T10:35:53.767+0000] {taskinstance.py:2653} INFO - 0 downstream tasks scheduled from follow-on schedule check
